<?xml version="1.0"?>
<sdf version="1.7">

  <!-- Note:
       This file defines the model for a box with two degrees of freedom
       (DOFs): a) one DOF for the horizontal motion along the y axis and
       b) one DOF for the vertical motion along the z axis.
       To this end, this model defines a small "ghost body" between
       the box and the world so that we can attach two prismatic joints for
       these two DOFs. The ghost body has negligible mass.
  -->
  <!-- world->ghost_body_y->ghost_body_z_sphere-->
  <model name="box">
    <!-- The model for a solid box of uniform density. -->
    <link name="ghost_body_y"></link>
    <link name="ghost_body_z"></link>

    <joint name="y_slider" type="prismatic">
      <parent>world</parent>
      <child>ghost_body_y</child>
      <axis>
        <xyz>1 0 0</xyz>
        <!-- Drake attaches an actuator to all joints with a non-zero effort
             limit. We do not want an actuator for this joint. -->
        <limit>
          <effort>0</effort>
        </limit>
        <dynamics>
          <damping>0.999999</damping>
          <spring_reference>0</spring_reference>
          <spring_stiffness>0</spring_stiffness>
        </dynamics>                
      </axis>
    </joint>

    <joint name="z_slider" type="prismatic">
      <parent>ghost_body_y</parent>
      <child>ghost_body_z</child>
      <axis>
        <xyz>0 1 0</xyz>
        <!-- Drake attaches an actuator to all joints with a non-zero effort
             limit. We do not want an actuator for this joint and therefore we
             set a zero effort limit. -->
        <limit>
          <effort>0</effort>
        </limit>
        <dynamics>
          <damping>0.999999</damping>
          <spring_reference>0</spring_reference>
          <spring_stiffness>0</spring_stiffness>
        </dynamics>        
      </axis>
    </joint>

    <joint name="rotation" type="revolute">
      <parent>ghost_body_z</parent>
      <child>box</child>
      <axis>
        <xyz>0 0 1</xyz>
        <!-- Drake attaches an actuator to all joints with a non-zero effort
             limit. We do not want an actuator for this joint and therefore we
             set a zero effort limit. -->
        <limit>
          <effort>0</effort>
        </limit>
        <dynamics>
          <damping>0.999999</damping>
          <spring_reference>0</spring_reference>
          <spring_stiffness>0</spring_stiffness>
        </dynamics>                
      </axis>
    </joint>

    <link name="box">
      <inertial>
        <mass>100.0</mass>

        <inertia>
          <ixx>10</ixx>
          <ixy>0</ixy>
          <ixz>0</ixz>
          <iyy>10</iyy>
          <iyz>0</iyz>
          <izz>10</izz>
        </inertia>
      </inertial>
      <pose>0 0 0.02 0 0 0</pose>

      <visual name="box_visual">
        <geometry>
          <box>
            <size>0.12 0.2 0.04</size>
          </box>
        </geometry>
        <material>
          <diffuse>0.8 0.8 0.8 0.8</diffuse>        
        </material>
      </visual>

      <collision name="collision">
        <geometry>
          <box>
            <size>0.12 0.2 0.04</size>
          </box>
        </geometry>
        <surface>
          <friction>
            <ode>
              <mu>1.0</mu>
              <mu2>1.0</mu2>
            </ode>
          </friction>
        </surface>
      </collision>
    </link>
  </model>

</sdf>